Workbook

Sheet README_HowToAudit
B2: FORMULA-DRIVEN MODEL - how to audit it
B4: Every number in this workbook that is not raw source data is an Excel formula.
B7: COLOUR CONVENTION
B8: BLUE text = raw input from the source dataset. These are the only hardcoded numbers.
B9: BLACK text = a formula computed on this sheet.
B10: GREEN text = a formula that links to another sheet.
B11: YELLOW fill = a key assumption or lever you can change.
B12: GREEN fill = a headline output.
B15: THE CALCULATION CHAIN
B16: Data_Monthly 1,830 raw monthly observations. The only source data in the file.
B17: |
B18: Data_Annual AVERAGEIFS collapses monthly to annual. Payout, yield, growth computed here.
... B41: LN(0.5)/LN(1-c) half-life - how many years to close half the adjustment gap

Sheet Summary
B2: HEADLINE RESULTS
B3: Every figure below is a link. Nothing on this sheet is calculated or typed.
A5: PAYOUT
B6: Median payout ratio, 1871-1900 | C6: =Smoothing_Calc!$F$5 -> 0.7173913
B7: Median payout ratio, 2009-2023 | C7: =Smoothing_Calc!$F$12 -> 0.40192894
B8: Median dividend yield, 1871-1900 | C8: =Smoothing_Calc!$G$5 -> 0.047835457
B9: Median dividend yield, 2009-2023 | C9: =Smoothing_Calc!$G$12 -> 0.019529782
A11: SMOOTHING
B12: Smoothing ratio, 1871-1900 | C12: =Smoothing_Calc!$E$5 -> 0.81725742 | D12: sd(div growth) / sd(earnings growth)
B13: Smoothing ratio, 2009-2023 | C13: =Smoothing_Calc!$E$12 -> 0.088891454
B14: Times smoother | C14: =Smoothing_Calc!$E$5/Smoothing_Calc!$E$12 -> 9.1938807
A16: LINTNER SPEED OF ADJUSTMENT
B17: c, 1871-1900 | C17: =Lintner_Calc!$E$161 -> 0.35672787
B18: c, 1946-1972 | C18: =Lintner_Calc!$E$164 -> 0.35071496
B19: c, 2009-2023 | C19: =Lintner_Calc!$E$168 -> 0.073357574 | D19: the collapse
B20: t-statistic, 2009-2023 | C20: =Lintner_Calc!$I$168 -> 0.88722561 | D20: below 2 = not statistically distinguishable from zero
B21: Mean c, five eras 1871-1981 | C21: =AVERAGE(Lintner_Calc!$E$161:$E$165) -> 0.36250458
B22: Mean c, three eras 1982-2023 | C22: =AVERAGE(Lintner_Calc!$E$166:$E$168) -> 0.094121693
B23: Pooled c, 1871-1981 | C23: =Lintner_Calc!$C$329 -> 0.18562001
B24: Pooled c, 1982-2023 | C24: =Lintner_Calc!$C$330 -> 0.11072532
A26: CRISES
B27: Great Depression - earnings fall | C27: =Crisis_Calc!$E$8 -> -0.71669898
B28: Great Depression - dividend fall | C28: =Crisis_Calc!$F$8 -> -0.48907104
B29: Global financial crisis - earnings fall | C29: =Crisis_Calc!$E$12 -> -0.79289848
B30: Global financial crisis - dividend fall | C30: =Crisis_Calc!$F$12 -> -0.040473029 | D30: the headline contrast
A32: CROSS-SECTION
B33: Firms in sample | C33: =Sector_Calc!$B$17 -> 466
B34: Share paying a dividend | C34: =Sector_Calc!$D$17 -> 0.82832618
B35: Life-cycle gradient | C35: =LifeCycle_Calc!$F$12 -> 0.22392362 | D35: oldest band less youngest

Sheet Data_Monthly
A1: RAW SOURCE DATA | Shiller S&P 500 monthly series | 1,830 observations | Jan-1871 to Jun-2023
A2: This is the ONLY sheet containing hardcoded numbers. Every other sheet computes from it. Source: https://raw.githubusercontent.com/datasets/s-and-p-500/main/data/data.csv
A4: Date | B4: Year | C4: S&P price | D4: Dividend | E4: Earnings | F4: CPI | G4: 10-year rate | H4: CAPE | I4: Payout ratio | J4: Dividend yield
A5: 1871-01 | B5: 1871 | C5: 4.44 | D5: 0.26 | E5: 0.4 | F5: 12.46 | G5: 5.32 | I5: =IFERROR($D5/$E5,"") -> 0.65 | J5: =IFERROR($D5/$C5,"") -> 0.058558559
A6: 1871-02 | B6: 1871 | C6: 4.5 | D6: 0.26 | E6: 0.4 | F6: 12.84 | G6: 5.32 | I6: =IFERROR($D6/$E6,"") -> 0.65 | J6: =IFERROR($D6/$C6,"") -> 0.057777778
A7: 1871-03 | B7: 1871 | C7: 4.61 | D7: 0.26 | E7: 0.4 | F7: 13.03 | G7: 5.33 | I7: =IFERROR($D7/$E7,"") -> 0.65 | J7: =IFERROR($D7/$C7,"") -> 0.056399132
A8: 1871-04 | B8: 1871 | C8: 4.74 | D8: 0.26 | E8: 0.4 | F8: 12.56 | G8: 5.33 | I8: =IFERROR($D8/$E8,"") -> 0.65 | J8: =IFERROR($D8/$C8,"") -> 0.054852321
A9: 1871-05 | B9: 1871 | C9: 4.86 | D9: 0.26 | E9: 0.4 | F9: 12.27 | G9: 5.33 | I9: =IFERROR($D9/$E9,"") -> 0.65 | J9: =IFERROR($D9/$C9,"") -> 0.053497942
A10: 1871-06 | B10: 1871 | C10: 4.82 | D10: 0.26 | E10: 0.4 | F10: 12.08 | G10: 5.34 | I10: =IFERROR($D10/$E10,"") -> 0.65 | J10: =IFERROR($D10/$C10,"") -> 0.053941909
A11: 1871-07 | B11: 1871 | C11: 4.73 | D11: 0.26 | E11: 0.4 | F11: 12.08 | G11: 5.34 | I11: =IFERROR($D11/$E11,"") -> 0.65 | J11: =IFERROR($D11/$C11,"") -> 0.054968288
A12: 1871-08 | B12: 1871 | C12: 4.79 | D12: 0.26 | E12: 0.4 | F12: 11.89 | G12: 5.34 | I12: =IFERROR($D12/$E12,"") -> 0.65 | J12: =IFERROR($D12/$C12,"") -> 0.054279749
A13: 1871-09 | B13: 1871 | C13: 4.84 | D13: 0.26 | E13: 0.4 | F13: 12.18 | G13: 5.35 | I13: =IFERROR($D13/$E13,"") -> 0.65 | J13: =IFERROR($D13/$C13,"") -> 0.053719008
A14: 1871-10 | B14: 1871 | C14: 4.59 | D14: 0.26 | E14: 0.4 | F14: 12.37 | G14: 5.35 | I14: =IFERROR($D14/$E14,"") -> 0.65 | J14: =IFERROR($D14/$C14,"") -> 0.05664488
A15: 1871-11 | B15: 1871 | C15: 4.64 | D15: 0.26 | E15: 0.4 | F15: 12.37 | G15: 5.35 | I15: =IFERROR($D15/$E15,"") -> 0.65 | J15: =IFERROR($D15/$C15,"") -> 0.056034483
A16: 1871-12 | B16: 1871 | C16: 4.74 | D16: 0.26 | E16: 0.4 | F16: 12.65 | G16: 5.36 | I16: =IFERROR($D16/$E16,"") -> 0.65 | J16: =IFERROR($D16/$C16,"") -> 0.054852321
... A124: 1880-12 | B124: 1880 | C124: 5.84 | D124: 0.26 | E124: 0.49 | F124: 9.51 | G124: 3.73 | I124: =IFERROR($D124/$E124,"") -> 0.53061224 | J124: =IFERROR($D124/$C124,"") -> 0.044520548
A125: 1881-01 | B125: 1881 | C125: 6.19 | D125: 0.265 | E125: 0.4858 | F125: 9.42 | G125: 3.7 | H125: 18.47 | I125: =IFERROR($D125/$E125,"") -> 0.54549197 | J125: =IFERROR($D125/$C125,"") -> 0.042810985
A126: 1881-02 | B126: 1881 | C126: 6.17 | D126: 0.27 | E126: 0.4817 | F126: 9.51 | G126: 3.69 | H126: 18.15 | I126: =IFERROR($D126/$E126,"") -> 0.56051484 | J126: =IFERROR($D126/$C126,"") -> 0.04376013
A127: 1881-03 | B127: 1881 | C127: 6.24 | D127: 0.275 | E127: 0.4775 | F127: 9.51 | G127: 3.69 | H127: 18.27 | I127: =IFERROR($D127/$E127,"") -> 0.57591623 | J127: =IFERROR($D127/$C127,"") -> 0.044070513
A128: 1881-04 | B128: 1881 | C128: 6.22 | D128: 0.28 | E128: 0.4733 | F128: 9.61 | G128: 3.68 | H128: 17.95 | I128: =IFERROR($D128/$E128,"") -> 0.59159096 | J128: =IFERROR($D128/$C128,"") -> 0.045016077
A129: 1881-05 | B129: 1881 | C129: 6.5 | D129: 0.285 | E129: 0.4692 | F129: 9.51 | G129: 3.67 | H129: 18.87 | I129: =IFERROR($D129/$E129,"") -> 0.60741688 | J129: =IFERROR($D129/$C129,"") -> 0.043846154
A130: 1881-06 | B130: 1881 | C130: 6.58 | D130: 0.29 | E130: 0.465 | F130: 9.51 | G130: 3.67 | H130: 19.03 | I130: =IFERROR($D130/$E130,"") -> 0.62365591 | J130: =IFERROR($D130/$C130,"") -> 0.044072948
A131: 1881-07 | B131: 1881 | C131: 6.35 | D131: 0.295 | E131: 0.4608 | F131: 9.61 | G131: 3.66 | H131: 18.12 | I131: =IFERROR($D131/$E131,"") -> 0.64019097 | J131: =IFERROR($D131/$C131,"") -> 0.046456693
A132: 1881-08 | B132: 1881 | C132: 6.2 | D132: 0.3 | E132: 0.4567 | F132: 9.8 | G132: 3.65 | H132: 17.29 | I132: =IFERROR($D132/$E132,"") -> 0.65688636 | J132: =IFERROR($D132/$C132,"") -> 0.048387097
A133: 1881-09 | B133: 1881 | C133: 6.25 | D133: 0.305 | E133: 0.4525 | F133: 10.18 | G133: 3.65 | H133: 16.72 | I133: =IFERROR($D133/$E133,"") -> 0.67403315 | J133: =IFERROR($D133/$C133,"") -> 0.0488
A134: 1881-10 | B134: 1881 | C134: 6.15 | D134: 0.31 | E134: 0.4483 | F134: 10.28 | G134: 3.64 | H134: 16.26 | I134: =IFERROR($D134/$E134,"") -> 0.69150123 | J134: =IFERROR($D134/$C134,"") -> 0.050406504
A135: 1881-11 | B135: 1881 | C135: 6.19 | D135: 0.315 | E135: 0.4442 | F135: 10.18 | G135: 3.63 | H135: 16.48 | I135: =IFERROR($D135/$E135,"") -> 0.70914003 | J135: =IFERROR($D135/$C135,"") -> 0.05088853
A136: 1881-12 | B136: 1881 | C136: 6.01 | D136: 0.32 | E136: 0.44 | F136: 10.18 | G136: 3.63 | H136: 15.96 | I136: =IFERROR($D136/$E136,"") -> 0.72727273 | J136: =IFERROR($D136/$C136,"") -> 0.053244592
... A1834: 2023-06 | B1834: 2023 | C1834: 4345.3729 | D1834: 68.71 | E1834: 181.17 | F1834: 305.11 | G1834: 3.75 | H1834: 29.94 | I1834: =IFERROR($D1834/$E1834,"") -> 0.37925705 | J1834: =IFERROR($D1834/$C1834,"") -> 0.015812222

Sheet Data_Annual
A1: ANNUAL SERIES | computed from Data_Monthly with AVERAGEIFS | 153 years
A2: Nothing here is typed in. Column A is the year; every other column is a formula. Click any cell and press F2.
A4: Year | B4: Price | C4: Dividend | D4: Earnings | E4: CPI | F4: CAPE | G4: Payout ratio | H4: Dividend yield | I4: Dividend growth | J4: Earnings growth
A5: 1871 | B5: =AVERAGEIFS(Data_Monthly!$C$5:$C$1834,Data_Monthly!$B$5:$B$1834,$A5) -> 4.6916667 | C5: =AVERAGEIFS(Data_Monthly!$D$5:$D$1834,Data_Monthly!$B$5:$B$1834,$A5) -> 0.26 | D5: =AVERAGEIFS(Data_Monthly!$E$5:$E$1834,Data_Monthly!$B$5:$B$1834,$A5) -> 0.4 | E5: =AVERAGEIFS(Data_Monthly!$F$5:$F$1834,Data_Monthly!$B$5:$B$1834,$A5) -> 12.398333 | F5: =IFERROR(AVERAGEIFS(Data_Monthly!$H$5:$H$1834,Data_Monthly!$B$5:$B$1834,$A5),"") | G5: =IFERROR($C5/$D5,"") -> 0.65 | H5: =IFERROR($C5/$B5,"") -> 0.055417407
A6: 1872 | B6: =AVERAGEIFS(Data_Monthly!$C$5:$C$1834,Data_Monthly!$B$5:$B$1834,$A6) -> 5.0291667 | C6: =AVERAGEIFS(Data_Monthly!$D$5:$D$1834,Data_Monthly!$B$5:$B$1834,$A6) -> 0.28166667 | D6: =AVERAGEIFS(Data_Monthly!$E$5:$E$1834,Data_Monthly!$B$5:$B$1834,$A6) -> 0.41625 | E6: =AVERAGEIFS(Data_Monthly!$F$5:$F$1834,Data_Monthly!$B$5:$B$1834,$A6) -> 12.921667 | F6: =IFERROR(AVERAGEIFS(Data_Monthly!$H$5:$H$1834,Data_Monthly!$B$5:$B$1834,$A6),"") | G6: =IFERROR($C6/$D6,"") -> 0.67667668 | H6: =IFERROR($C6/$B6,"") -> 0.056006628 | I6: =IFERROR($C6/$C5-1,"") -> 0.083333333 | J6: =IFERROR($D6/$D5-1,"") -> 0.040625
A7: 1873 | B7: =AVERAGEIFS(Data_Monthly!$C$5:$C$1834,Data_Monthly!$B$5:$B$1834,$A7) -> 4.8016667 | C7: =AVERAGEIFS(Data_Monthly!$D$5:$D$1834,Data_Monthly!$B$5:$B$1834,$A7) -> 0.31625 | D7: =AVERAGEIFS(Data_Monthly!$E$5:$E$1834,Data_Monthly!$B$5:$B$1834,$A7) -> 0.44625 | E7: =AVERAGEIFS(Data_Monthly!$F$5:$F$1834,Data_Monthly!$B$5:$B$1834,$A7) -> 12.679167 | F7: =IFERROR(AVERAGEIFS(Data_Monthly!$H$5:$H$1834,Data_Monthly!$B$5:$B$1834,$A7),"") | G7: =IFERROR($C7/$D7,"") -> 0.70868347 | H7: =IFERROR($C7/$B7,"") -> 0.065862548 | I7: =IFERROR($C7/$C6-1,"") -> 0.12278107 | J7: =IFERROR($D7/$D6-1,"") -> 0.072072072
A8: 1874 | B8: =AVERAGEIFS(Data_Monthly!$C$5:$C$1834,Data_Monthly!$B$5:$B$1834,$A8) -> 4.57 | C8: =AVERAGEIFS(Data_Monthly!$D$5:$D$1834,Data_Monthly!$B$5:$B$1834,$A8) -> 0.33 | D8: =AVERAGEIFS(Data_Monthly!$E$5:$E$1834,Data_Monthly!$B$5:$B$1834,$A8) -> 0.46 | E8: =AVERAGEIFS(Data_Monthly!$F$5:$F$1834,Data_Monthly!$B$5:$B$1834,$A8) -> 11.940833 | F8: =IFERROR(AVERAGEIFS(Data_Monthly!$H$5:$H$1834,Data_Monthly!$B$5:$B$1834,$A8),"") | G8: =IFERROR($C8/$D8,"") -> 0.7173913 | H8: =IFERROR($C8/$B8,"") -> 0.072210066 | I8: =IFERROR($C8/$C7-1,"") -> 0.043478261 | J8: =IFERROR($D8/$D7-1,"") -> 0.030812325
A9: 1875 | B9: =AVERAGEIFS(Data_Monthly!$C$5:$C$1834,Data_Monthly!$B$5:$B$1834,$A9) -> 4.4475 | C9: =AVERAGEIFS(Data_Monthly!$D$5:$D$1834,Data_Monthly!$B$5:$B$1834,$A9) -> 0.31375 | D9: =AVERAGEIFS(Data_Monthly!$E$5:$E$1834,Data_Monthly!$B$5:$B$1834,$A9) -> 0.40583333 | E9: =AVERAGEIFS(Data_Monthly!$F$5:$F$1834,Data_Monthly!$B$5:$B$1834,$A9) -> 11.265833 | F9: =IFERROR(AVERAGEIFS(Data_Monthly!$H$5:$H$1834,Data_Monthly!$B$5:$B$1834,$A9),"") | G9: =IFERROR($C9/$D9,"") -> 0.77310062 | H9: =IFERROR($C9/$B9,"") -> 0.07054525 | I9: =IFERROR($C9/$C8-1,"") -> -0.049242424 | J9: =IFERROR($D9/$D8-1,"") -> -0.11775362
A10: 1876 | B10: =AVERAGEIFS(Data_Monthly!$C$5:$C$1834,Data_Monthly!$B$5:$B$1834,$A10) -> 4.0608333 | C10: =AVERAGEIFS(Data_Monthly!$D$5:$D$1834,Data_Monthly!$B$5:$B$1834,$A10) -> 0.3 | D10: =AVERAGEIFS(Data_Monthly!$E$5:$E$1834,Data_Monthly!$B$5:$B$1834,$A10) -> 0.31666667 | E10: =AVERAGEIFS(Data_Monthly!$F$5:$F$1834,Data_Monthly!$B$5:$B$1834,$A10) -> 10.5075 | F10: =IFERROR(AVERAGEIFS(Data_Monthly!$H$5:$H$1834,Data_Monthly!$B$5:$B$1834,$A10),"") | G10: =IFERROR($C10/$D10,"") -> 0.94736842 | H10: =IFERROR($C10/$B10,"") -> 0.073876462 | I10: =IFERROR($C10/$C9-1,"") -> -0.043824701 | J10: =IFERROR($D10/$D9-1,"") -> -0.21971253
A11: 1877 | B11: =AVERAGEIFS(Data_Monthly!$C$5:$C$1834,Data_Monthly!$B$5:$B$1834,$A11) -> 3.1358333 | C11: =AVERAGEIFS(Data_Monthly!$D$5:$D$1834,Data_Monthly!$B$5:$B$1834,$A11) -> 0.24041667 | D11: =AVERAGEIFS(Data_Monthly!$E$5:$E$1834,Data_Monthly!$B$5:$B$1834,$A11) -> 0.29083333 | E11: =AVERAGEIFS(Data_Monthly!$F$5:$F$1834,Data_Monthly!$B$5:$B$1834,$A11) -> 10.116667 | F11: =IFERROR(AVERAGEIFS(Data_Monthly!$H$5:$H$1834,Data_Monthly!$B$5:$B$1834,$A11),"") | G11: =IFERROR($C11/$D11,"") -> 0.82664756 | H11: =IFERROR($C11/$B11,"") -> 0.076667552 | I11: =IFERROR($C11/$C10-1,"") -> -0.19861111 | J11: =IFERROR($D11/$D10-1,"") -> -0.081578947
A12: 1878 | B12: =AVERAGEIFS(Data_Monthly!$C$5:$C$1834,Data_Monthly!$B$5:$B$1834,$A12) -> 3.3833333 | C12: =AVERAGEIFS(Data_Monthly!$D$5:$D$1834,Data_Monthly!$B$5:$B$1834,$A12) -> 0.18458333 | D12: =AVERAGEIFS(Data_Monthly!$E$5:$E$1834,Data_Monthly!$B$5:$B$1834,$A12) -> 0.30541667 | E12: =AVERAGEIFS(Data_Monthly!$F$5:$F$1834,Data_Monthly!$B$5:$B$1834,$A12) -> 8.6408333 | F12: =IFERROR(AVERAGEIFS(Data_Monthly!$H$5:$H$1834,Data_Monthly!$B$5:$B$1834,$A12),"") | G12: =IFERROR($C12/$D12,"") -> 0.60436562 | H12: =IFERROR($C12/$B12,"") -> 0.05455665 | I12: =IFERROR($C12/$C11-1,"") -> -0.2322357 | J12: =IFERROR($D12/$D11-1,"") -> 0.050143266
A13: 1879 | B13: =AVERAGEIFS(Data_Monthly!$C$5:$C$1834,Data_Monthly!$B$5:$B$1834,$A13) -> 4.1225 | C13: =AVERAGEIFS(Data_Monthly!$D$5:$D$1834,Data_Monthly!$B$5:$B$1834,$A13) -> 0.19083333 | D13: =AVERAGEIFS(Data_Monthly!$E$5:$E$1834,Data_Monthly!$B$5:$B$1834,$A13) -> 0.34791667 | E13: =AVERAGEIFS(Data_Monthly!$F$5:$F$1834,Data_Monthly!$B$5:$B$1834,$A13) -> 8.5225 | F13: =IFERROR(AVERAGEIFS(Data_Monthly!$H$5:$H$1834,Data_Monthly!$B$5:$B$1834,$A13),"") | G13: =IFERROR($C13/$D13,"") -> 0.54850299 | H13: =IFERROR($C13/$B13,"") -> 0.046290681 | I13: =IFERROR($C13/$C12-1,"") -> 0.033860045 | J13: =IFERROR($D13/$D12-1,"") -> 0.13915416
A14: 1880 | B14: =AVERAGEIFS(Data_Monthly!$C$5:$C$1834,Data_Monthly!$B$5:$B$1834,$A14) -> 5.2091667 | C14: =AVERAGEIFS(Data_Monthly!$D$5:$D$1834,Data_Monthly!$B$5:$B$1834,$A14) -> 0.2325 | D14: =AVERAGEIFS(Data_Monthly!$E$5:$E$1834,Data_Monthly!$B$5:$B$1834,$A14) -> 0.43958333 | E14: =AVERAGEIFS(Data_Monthly!$F$5:$F$1834,Data_Monthly!$B$5:$B$1834,$A14) -> 9.5375 | F14: =IFERROR(AVERAGEIFS(Data_Monthly!$H$5:$H$1834,Data_Monthly!$B$5:$B$1834,$A14),"") | G14: =IFERROR($C14/$D14,"") -> 0.52890995 | H14: =IFERROR($C14/$B14,"") -> 0.044632859 | I14: =IFERROR($C14/$C13-1,"") -> 0.21834061 | J14: =IFERROR($D14/$D13-1,"") -> 0.26347305
A15: 1881 | B15: =AVERAGEIFS(Data_Monthly!$C$5:$C$1834,Data_Monthly!$B$5:$B$1834,$A15) -> 6.2541667 | C15: =AVERAGEIFS(Data_Monthly!$D$5:$D$1834,Data_Monthly!$B$5:$B$1834,$A15) -> 0.2925 | D15: =AVERAGEIFS(Data_Monthly!$E$5:$E$1834,Data_Monthly!$B$5:$B$1834,$A15) -> 0.46291667 | E15: =AVERAGEIFS(Data_Monthly!$F$5:$F$1834,Data_Monthly!$B$5:$B$1834,$A15) -> 9.775 | F15: =IFERROR(AVERAGEIFS(Data_Monthly!$H$5:$H$1834,Data_Monthly!$B$5:$B$1834,$A15),"") -> 17.630833 | G15: =IFERROR($C15/$D15,"") -> 0.63186319 | H15: =IFERROR($C15/$B15,"") -> 0.046768821 | I15: =IFERROR($C15/$C14-1,"") -> 0.25806452 | J15: =IFERROR($D15/$D14-1,"") -> 0.053080569
A16: 1882 | B16: =AVERAGEIFS(Data_Monthly!$C$5:$C$1834,Data_Monthly!$B$5:$B$1834,$A16) -> 5.9 | C16: =AVERAGEIFS(Data_Monthly!$D$5:$D$1834,Data_Monthly!$B$5:$B$1834,$A16) -> 0.32 | D16: =AVERAGEIFS(Data_Monthly!$E$5:$E$1834,Data_Monthly!$B$5:$B$1834,$A16) -> 0.43458333 | E16: =AVERAGEIFS(Data_Monthly!$F$5:$F$1834,Data_Monthly!$B$5:$B$1834,$A16) -> 10.309167 | F16: =IFERROR(AVERAGEIFS(Data_Monthly!$H$5:$H$1834,Data_Monthly!$B$5:$B$1834,$A16),"") -> 15.243333 | G16: =IFERROR($C16/$D16,"") -> 0.73633749 | H16: =IFERROR($C16/$B16,"") -> 0.054237288 | I16: =IFERROR($C16/$C15-1,"") -> 0.094017094 | J16: =IFERROR($D16/$D15-1,"") -> -0.061206121
A17: 1883 | B17: =AVERAGEIFS(Data_Monthly!$C$5:$C$1834,Data_Monthly!$B$5:$B$1834,$A17) -> 5.6341667 | C17: =AVERAGEIFS(Data_Monthly!$D$5:$D$1834,Data_Monthly!$B$5:$B$1834,$A17) -> 0.32541667 | D17: =AVERAGEIFS(Data_Monthly!$E$5:$E$1834,Data_Monthly!$B$5:$B$1834,$A17) -> 0.41375 | E17: =AVERAGEIFS(Data_Monthly!$F$5:$F$1834,Data_Monthly!$B$5:$B$1834,$A17) -> 9.5616667 | F17: =IFERROR(AVERAGEIFS(Data_Monthly!$H$5:$H$1834,Data_Monthly!$B$5:$B$1834,$A17),"") -> 15.316667 | G17: =IFERROR($C17/$D17,"") -> 0.78650554 | H17: =IFERROR($C17/$B17,"") -> 0.057757728 | I17: =IFERROR($C17/$C16-1,"") -> 0.016927083 | J17: =IFERROR($D17/$D16-1,"") -> -0.047938639
... A157: 2023 | B157: =AVERAGEIFS(Data_Monthly!$C$5:$C$1834,Data_Monthly!$B$5:$B$1834,$A157) -> 4103.6523 | C157: =AVERAGEIFS(Data_Monthly!$D$5:$D$1834,Data_Monthly!$B$5:$B$1834,$A157) -> 68.161667 | D157: =AVERAGEIFS(Data_Monthly!$E$5:$E$1834,Data_Monthly!$B$5:$B$1834,$A157) -> 176.76667 | E157: =AVERAGEIFS(Data_Monthly!$F$5:$F$1834,Data_Monthly!$B$5:$B$1834,$A157) -> 302.38 | F157: =IFERROR(AVERAGEIFS(Data_Monthly!$H$5:$H$1834,Data_Monthly!$B$5:$B$1834,$A157),"") -> 28.776667 | G157: =IFERROR($C157/$D157,"") -> 0.38560249 | H157: =IFERROR($C157/$B157,"") -> 0.01661 | I157: =IFERROR($C157/$C156-1,"") -> 0.064801496 | J157: =IFERROR($D157/$D156-1,"") -> -0.067837948

Sheet Lintner_Calc
A1: LINTNER PARTIAL-ADJUSTMENT MODEL | built column by column | every step visible
A2: Model: change in DPS = a + c x (target payout x EPS - lagged DPS). The coefficient c is the speed of adjustment. Each era is a contiguous block of rows, so the regression uses simple ranges you can read directly.
A4: Year | B4: Era | C4: Dividend | D4: Earnings | E4: Payout | F4: Lagged dividend | G4: y = change in dividend | H4: Target payout r | I4: x = gap
A5: 1871 | B5: 1871-1900 Gilded Age | C5: =Data_Annual!$C$5 -> 0.26 | D5: =Data_Annual!$D$5 -> 0.4 | E5: =IFERROR($C5/$D5,"") -> 0.65
A6: 1872 | B6: 1871-1900 Gilded Age | C6: =Data_Annual!$C$6 -> 0.28166667 | D6: =Data_Annual!$D$6 -> 0.41625 | E6: =IFERROR($C6/$D6,"") -> 0.67667668 | F6: =$C5 -> 0.26 | G6: =$C6-$F6 -> 0.021666667 | H6: =$D$161 -> 0.7268644 | I6: =$H6*$D6-$F6 -> 0.042557305
A7: 1873 | B7: 1871-1900 Gilded Age | C7: =Data_Annual!$C$7 -> 0.31625 | D7: =Data_Annual!$D$7 -> 0.44625 | E7: =IFERROR($C7/$D7,"") -> 0.70868347 | F7: =$C6 -> 0.28166667 | G7: =$C7-$F7 -> 0.034583333 | H7: =$D$161 -> 0.7268644 | I7: =$H7*$D7-$F7 -> 0.04269657
A8: 1874 | B8: 1871-1900 Gilded Age | C8: =Data_Annual!$C$8 -> 0.33 | D8: =Data_Annual!$D$8 -> 0.46 | E8: =IFERROR($C8/$D8,"") -> 0.7173913 | F8: =$C7 -> 0.31625 | G8: =$C8-$F8 -> 0.01375 | H8: =$D$161 -> 0.7268644 | I8: =$H8*$D8-$F8 -> 0.018107622
A9: 1875 | B9: 1871-1900 Gilded Age | C9: =Data_Annual!$C$9 -> 0.31375 | D9: =Data_Annual!$D$9 -> 0.40583333 | E9: =IFERROR($C9/$D9,"") -> 0.77310062 | F9: =$C8 -> 0.33 | G9: =$C9-$F9 -> -0.01625 | H9: =$D$161 -> 0.7268644 | I9: =$H9*$D9-$F9 -> -0.035014199
A10: 1876 | B10: 1871-1900 Gilded Age | C10: =Data_Annual!$C$10 -> 0.3 | D10: =Data_Annual!$D$10 -> 0.31666667 | E10: =IFERROR($C10/$D10,"") -> 0.94736842 | F10: =$C9 -> 0.31375 | G10: =$C10-$F10 -> -0.01375 | H10: =$D$161 -> 0.7268644 | I10: =$H10*$D10-$F10 -> -0.083576275
A11: 1877 | B11: 1871-1900 Gilded Age | C11: =Data_Annual!$C$11 -> 0.24041667 | D11: =Data_Annual!$D$11 -> 0.29083333 | E11: =IFERROR($C11/$D11,"") -> 0.82664756 | F11: =$C10 -> 0.3 | G11: =$C11-$F11 -> -0.059583333 | H11: =$D$161 -> 0.7268644 | I11: =$H11*$D11-$F11 -> -0.088603605
A12: 1878 | B12: 1871-1900 Gilded Age | C12: =Data_Annual!$C$12 -> 0.18458333 | D12: =Data_Annual!$D$12 -> 0.30541667 | E12: =IFERROR($C12/$D12,"") -> 0.60436562 | F12: =$C11 -> 0.24041667 | G12: =$C12-$F12 -> -0.055833333 | H12: =$D$161 -> 0.7268644 | I12: =$H12*$D12-$F12 -> -0.018420166
A13: 1879 | B13: 1871-1900 Gilded Age | C13: =Data_Annual!$C$13 -> 0.19083333 | D13: =Data_Annual!$D$13 -> 0.34791667 | E13: =IFERROR($C13/$D13,"") -> 0.54850299 | F13: =$C12 -> 0.18458333 | G13: =$C13-$F13 -> 0.00625 | H13: =$D$161 -> 0.7268644 | I13: =$H13*$D13-$F13 -> 0.068304905
A14: 1880 | B14: 1871-1900 Gilded Age | C14: =Data_Annual!$C$14 -> 0.2325 | D14: =Data_Annual!$D$14 -> 0.43958333 | E14: =IFERROR($C14/$D14,"") -> 0.52890995 | F14: =$C13 -> 0.19083333 | G14: =$C14-$F14 -> 0.041666667 | H14: =$D$161 -> 0.7268644 | I14: =$H14*$D14-$F14 -> 0.12868414
A15: 1881 | B15: 1871-1900 Gilded Age | C15: =Data_Annual!$C$15 -> 0.2925 | D15: =Data_Annual!$D$15 -> 0.46291667 | E15: =IFERROR($C15/$D15,"") -> 0.63186319 | F15: =$C14 -> 0.2325 | G15: =$C15-$F15 -> 0.06 | H15: =$D$161 -> 0.7268644 | I15: =$H15*$D15-$F15 -> 0.10397764
A16: 1882 | B16: 1871-1900 Gilded Age | C16: =Data_Annual!$C$16 -> 0.32 | D16: =Data_Annual!$D$16 -> 0.43458333 | E16: =IFERROR($C16/$D16,"") -> 0.73633749 | F16: =$C15 -> 0.2925 | G16: =$C16-$F16 -> 0.0275 | H16: =$D$161 -> 0.7268644 | I16: =$H16*$D16-$F16 -> 0.023383152
A17: 1883 | B17: 1871-1900 Gilded Age | C17: =Data_Annual!$C$17 -> 0.32541667 | D17: =Data_Annual!$D$17 -> 0.41375 | E17: =IFERROR($C17/$D17,"") -> 0.78650554 | F17: =$C16 -> 0.32 | G17: =$C17-$F17 -> 0.0054166667 | H17: =$D$161 -> 0.7268644 | I17: =$H17*$D17-$F17 -> -0.019259856
A18: 1884 | B18: 1871-1900 Gilded Age | C18: =Data_Annual!$C$18 -> 0.31916667 | D18: =Data_Annual!$D$18 -> 0.35125 | E18: =IFERROR($C18/$D18,"") -> 0.90865955 | F18: =$C17 -> 0.32541667 | G18: =$C18-$F18 -> -0.00625 | H18: =$D$161 -> 0.7268644 | I18: =$H18*$D18-$F18 -> -0.070105548
A19: 1885 | B19: 1871-1900 Gilded Age | C19: =Data_Annual!$C$19 -> 0.27208333 | D19: =Data_Annual!$D$19 -> 0.28833333 | E19: =IFERROR($C19/$D19,"") -> 0.94364162 | F19: =$C18 -> 0.31916667 | G19: =$C19-$F19 -> -0.047083333 | H19: =$D$161 -> 0.7268644 | I19: =$H19*$D19-$F19 -> -0.10958743
A20: 1886 | B20: 1871-1900 Gilded Age | C20: =Data_Annual!$C$20 -> 0.22916667 | D20: =Data_Annual!$D$20 -> 0.3025 | E20: =IFERROR($C20/$D20,"") -> 0.75757576 | F20: =$C19 -> 0.27208333 | G20: =$C20-$F20 -> -0.042916667 | H20: =$D$161 -> 0.7268644 | I20: =$H20*$D20-$F20 -> -0.052206853
A21: 1887 | B21: 1871-1900 Gilded Age | C21: =Data_Annual!$C$21 -> 0.23625 | D21: =Data_Annual!$D$21 -> 0.34625 | E21: =IFERROR($C21/$D21,"") -> 0.68231047 | F21: =$C20 -> 0.22916667 | G21: =$C21-$F21 -> 0.0070833333 | H21: =$D$161 -> 0.7268644 | I21: =$H21*$D21-$F21 -> 0.022510131
A22: 1888 | B22: 1871-1900 Gilded Age | C22: =Data_Annual!$C$22 -> 0.23916667 | D22: =Data_Annual!$D$22 -> 0.30583333 | E22: =IFERROR($C22/$D22,"") -> 0.78201635 | F22: =$C21 -> 0.23625 | G22: =$C22-$F22 -> 0.0029166667 | H22: =$D$161 -> 0.7268644 | I22: =$H22*$D22-$F22 -> -0.013950639
A23: 1889 | B23: 1871-1900 Gilded Age | C23: =Data_Annual!$C$23 -> 0.22458333 | D23: =Data_Annual!$D$23 -> 0.28166667 | E23: =IFERROR($C23/$D23,"") -> 0.79733728 | F23: =$C22 -> 0.23916667 | G23: =$C23-$F23 -> -0.014583333 | H23: =$D$161 -> 0.7268644 | I23: =$H23*$D23-$F23 -> -0.034433195
A24: 1890 | B24: 1871-1900 Gilded Age | C24: =Data_Annual!$C$24 -> 0.22 | D24: =Data_Annual!$D$24 -> 0.29458333 | E24: =IFERROR($C24/$D24,"") -> 0.74681754 | F24: =$C23 -> 0.22458333 | G24: =$C24-$F24 -> -0.0045833333 | H24: =$D$161 -> 0.7268644 | I24: =$H24*$D24-$F24 -> -0.010461197
A25: 1891 | B25: 1871-1900 Gilded Age | C25: =Data_Annual!$C$25 -> 0.22 | D25: =Data_Annual!$D$25 -> 0.31708333 | E25: =IFERROR($C25/$D25,"") -> 0.69382392 | F25: =$C24 -> 0.22 | G25: =$C25-$F25 -> 0 | H25: =$D$161 -> 0.7268644 | I25: =$H25*$D25-$F25 -> 0.010476586
A26: 1892 | B26: 1871-1900 Gilded Age | C26: =Data_Annual!$C$26 -> 0.23083333 | D26: =Data_Annual!$D$26 -> 0.35625 | E26: =IFERROR($C26/$D26,"") -> 0.64795322 | F26: =$C25 -> 0.22 | G26: =$C26-$F26 -> 0.010833333 | H26: =$D$161 -> 0.7268644 | I26: =$H26*$D26-$F26 -> 0.038945441
A27: 1893 | B27: 1871-1900 Gilded Age | C27: =Data_Annual!$C$27 -> 0.24541667 | D27: =Data_Annual!$D$27 -> 0.31041667 | E27: =IFERROR($C27/$D27,"") -> 0.79060403 | F27: =$C26 -> 0.23083333 | G27: =$C27-$F27 -> 0.014583333 | H27: =$D$161 -> 0.7268644 | I27: =$H27*$D27-$F27 -> -0.0052025104
A28: 1894 | B28: 1871-1900 Gilded Age | C28: =Data_Annual!$C$28 -> 0.22833333 | D28: =Data_Annual!$D$28 -> 0.20583333 | E28: =IFERROR($C28/$D28,"") -> 1.1093117 | F28: =$C27 -> 0.24541667 | G28: =$C28-$F28 -> -0.017083333 | H28: =$D$161 -> 0.7268644 | I28: =$H28*$D28-$F28 -> -0.095803745
A29: 1895 | B29: 1871-1900 Gilded Age | C29: =Data_Annual!$C$29 -> 0.19916667 | D29: =Data_Annual!$D$29 -> 0.20875 | E29: =IFERROR($C29/$D29,"") -> 0.95409182 | F29: =$C28 -> 0.22833333 | G29: =$C29-$F29 -> -0.029166667 | H29: =$D$161 -> 0.7268644 | I29: =$H29*$D29-$F29 -> -0.076600391
A30: 1896 | B30: 1871-1900 Gilded Age | C30: =Data_Annual!$C$30 -> 0.18458333 | D30: =Data_Annual!$D$30 -> 0.22833333 | E30: =IFERROR($C30/$D30,"") -> 0.80839416 | F30: =$C29 -> 0.19916667 | G30: =$C30-$F30 -> -0.014583333 | H30: =$D$161 -> 0.7268644 | I30: =$H30*$D30-$F30 -> -0.033199296
A31: 1897 | B31: 1871-1900 Gilded Age | C31: =Data_Annual!$C$31 -> 0.18 | D31: =Data_Annual!$D$31 -> 0.26416667 | E31: =IFERROR($C31/$D31,"") -> 0.68138801 | F31: =$C30 -> 0.18458333 | G31: =$C31-$F31 -> -0.0045833333 | H31: =$D$161 -> 0.7268644 | I31: =$H31*$D31-$F31 -> 0.0074300113
A32: 1898 | B32: 1871-1900 Gilded Age | C32: =Data_Annual!$C$32 -> 0.19083333 | D32: =Data_Annual!$D$32 -> 0.33166667 | E32: =IFERROR($C32/$D32,"") -> 0.57537688 | F32: =$C31 -> 0.18 | G32: =$C32-$F32 -> 0.010833333 | H32: =$D$161 -> 0.7268644 | I32: =$H32*$D32-$F32 -> 0.061076691
A33: 1899 | B33: 1871-1900 Gilded Age | C33: =Data_Annual!$C$33 -> 0.20541667 | D33: =Data_Annual!$D$33 -> 0.42041667 | E33: =IFERROR($C33/$D33,"") -> 0.48860258 | F33: =$C32 -> 0.19083333 | G33: =$C33-$F33 -> 0.014583333 | H33: =$D$161 -> 0.7268644 | I33: =$H33*$D33-$F33 -> 0.11475257
A34: 1900 | B34: 1871-1900 Gilded Age | C34: =Data_Annual!$C$34 -> 0.25875 | D34: =Data_Annual!$D$34 -> 0.48 | E34: =IFERROR($C34/$D34,"") -> 0.5390625 | F34: =$C33 -> 0.20541667 | G34: =$C34-$F34 -> 0.053333333 | H34: =$D$161 -> 0.7268644 | I34: =$H34*$D34-$F34 -> 0.14347824
A35: 1901 | B35: 1901-1929 Pre-Crash | C35: =Data_Annual!$C$35 -> 0.31083333 | D35: =Data_Annual!$D$35 -> 0.49083333 | E35: =IFERROR($C35/$D35,"") -> 0.63327674 | F35: =$C34 -> 0.25875 | G35: =$C35-$F35 -> 0.052083333 | H35: =$D$162 -> 0.60814179 | I35: =$H35*$D35-$F35 -> 0.039746261
A36: 1902 | B36: 1901-1929 Pre-Crash | C36: =Data_Annual!$C$36 -> 0.32541667 | D36: =Data_Annual!$D$36 -> 0.57041667 | E36: =IFERROR($C36/$D36,"") -> 0.57048941 | F36: =$C35 -> 0.31083333 | G36: =$C36-$F36 -> 0.014583333 | H36: =$D$162 -> 0.60814179 | I36: =$H36*$D36-$F36 -> 0.036060879
A37: 1903 | B37: 1901-1929 Pre-Crash | C37: =Data_Annual!$C$37 -> 0.34083333 | D37: =Data_Annual!$D$37 -> 0.57583333 | E37: =IFERROR($C37/$D37,"") -> 0.5918958 | F37: =$C36 -> 0.32541667 | G37: =$C37-$F37 -> 0.015416667 | H37: =$D$162 -> 0.60814179 | I37: =$H37*$D37-$F37 -> 0.024771647
A38: 1904 | B38: 1901-1929 Pre-Crash | C38: =Data_Annual!$C$38 -> 0.32833333 | D38: =Data_Annual!$D$38 -> 0.50833333 | E38: =IFERROR($C38/$D38,"") -> 0.64590164 | F38: =$C37 -> 0.34083333 | G38: =$C38-$F38 -> -0.0125 | H38: =$D$162 -> 0.60814179 | I38: =$H38*$D38-$F38 -> -0.031694591
A39: 1905 | B39: 1901-1929 Pre-Crash | C39: =Data_Annual!$C$39 -> 0.32083333 | D39: =Data_Annual!$D$39 -> 0.5875 | E39: =IFERROR($C39/$D39,"") -> 0.54609929 | F39: =$C38 -> 0.32833333 | G39: =$C39-$F39 -> -0.0075 | H39: =$D$162 -> 0.60814179 | I39: =$H39*$D39-$F39 -> 0.028949968
A40: 1906 | B40: 1901-1929 Pre-Crash | C40: =Data_Annual!$C$40 -> 0.36791667 | D40: =Data_Annual!$D$40 -> 0.71875 | E40: =IFERROR($C40/$D40,"") -> 0.51188406 | F40: =$C39 -> 0.32083333 | G40: =$C40-$F40 -> 0.047083333 | H40: =$D$162 -> 0.60814179 | I40: =$H40*$D40-$F40 -> 0.11626858
A41: 1907 | B41: 1901-1929 Pre-Crash | C41: =Data_Annual!$C$41 -> 0.42166667 | D41: =Data_Annual!$D$41 -> 0.70583333 | E41: =IFERROR($C41/$D41,"") -> 0.5974026 | F41: =$C40 -> 0.36791667 | G41: =$C41-$F41 -> 0.05375 | H41: =$D$162 -> 0.60814179 | I41: =$H41*$D41-$F41 -> 0.061330079
...

Sheet Smoothing_Calc
A1: SMOOTHING RATIO | STDEV(dividend growth) / STDEV(earnings growth) | by era
A2: Scale-free: it cannot be dismissed as 'dividends are just smaller now'. Lower means the dividend is smoother relative to earnings.
A4: Era | B4: Annual rows | C4: sd(dividend growth) | D4: sd(earnings growth) | E4: Smoothing ratio | F4: Median payout (monthly) | G4: Median yield (monthly)
A5: 1871-1900 Gilded Age | B5: ="6:34" -> 6:34 | C5: =STDEV(Data_Annual!$I$6:$I$34) -> 0.12064017 | D5: =STDEV(Data_Annual!$J$6:$J$34) -> 0.14761588 | E5: =IFERROR($C5/$D5,"") -> 0.81725742 | F5: =MEDIAN(Data_Monthly!$I$5:$I$364) -> 0.7173913 | G5: =MEDIAN(Data_Monthly!$J$5:$J$364) -> 0.047835457
A6: 1901-1929 Pre-Crash | B6: ="36:63" -> 36:63 | C6: =STDEV(Data_Annual!$I$36:$I$63) -> 0.087166436 | D6: =STDEV(Data_Annual!$J$36:$J$63) -> 0.23227076 | E6: =IFERROR($C6/$D6,"") -> 0.37527942 | F6: =MEDIAN(Data_Monthly!$I$365:$I$712) -> 0.6098106 | G6: =MEDIAN(Data_Monthly!$J$365:$J$712) -> 0.051904583
A7: 1930-1945 Depression & War | B7: ="65:79" -> 65:79 | C7: =STDEV(Data_Annual!$I$65:$I$79) -> 0.18591669 | D7: =STDEV(Data_Annual!$J$65:$J$79) -> 0.26967232 | E7: =IFERROR($C7/$D7,"") -> 0.68941703 | F7: =MEDIAN(Data_Monthly!$I$713:$I$904) -> 0.6880457 | G7: =MEDIAN(Data_Monthly!$J$713:$J$904) -> 0.050731543
A8: 1946-1972 Post-war boom | B8: ="81:106" -> 81:106 | C8: =STDEV(Data_Annual!$I$81:$I$106) -> 0.069637561 | D8: =STDEV(Data_Annual!$J$81:$J$106) -> 0.1441037 | E8: =IFERROR($C8/$D8,"") -> 0.48324616 | F8: =MEDIAN(Data_Monthly!$I$905:$I$1228) -> 0.54747077 | G8: =MEDIAN(Data_Monthly!$J$905:$J$1228) -> 0.036312131
A9: 1973-1981 Stagflation | B9: ="108:115" -> 108:115 | C9: =STDEV(Data_Annual!$I$108:$I$115) -> 0.038044797 | D9: =STDEV(Data_Annual!$J$108:$J$115) -> 0.096613747 | E9: =IFERROR($C9/$D9,"") -> 0.39378244 | F9: =MEDIAN(Data_Monthly!$I$1229:$I$1336) -> 0.41843122 | G9: =MEDIAN(Data_Monthly!$J$1229:$J$1336) -> 0.046793293
A10: 1982-1999 Buyback era begins | B10: ="117:133" -> 117:133 | C10: =STDEV(Data_Annual!$I$117:$I$133) -> 0.031231722 | D10: =STDEV(Data_Annual!$J$117:$J$133) -> 0.15523592 | E10: =IFERROR($C10/$D10,"") -> 0.20118876 | F10: =MEDIAN(Data_Monthly!$I$1337:$I$1552) -> 0.48531509 | G10: =MEDIAN(Data_Monthly!$J$1337:$J$1552) -> 0.031232451
A11: 2000-2008 Dot-com to GFC | B11: ="135:142" -> 135:142 | C11: =STDEV(Data_Annual!$I$135:$I$142) -> 0.066017878 | D11: =STDEV(Data_Annual!$J$135:$J$142) -> 0.32890374 | E11: =IFERROR($C11/$D11,"") -> 0.20072097 | F11: =MEDIAN(Data_Monthly!$I$1553:$I$1660) -> 0.34169314 | G11: =MEDIAN(Data_Monthly!$J$1553:$J$1660) -> 0.017288677
A12: 2009-2023 Post-GFC | B12: ="144:157" -> 144:157 | C12: =STDEV(Data_Annual!$I$144:$I$157) -> 0.072564021 | D12: =STDEV(Data_Annual!$J$144:$J$157) -> 0.81632169 | E12: =IFERROR($C12/$D12,"") -> 0.088891454 | F12: =MEDIAN(Data_Monthly!$I$1661:$I$1834) -> 0.40192894 | G12: =MEDIAN(Data_Monthly!$J$1661:$J$1834) -> 0.019529782
A14: Smoothing ratio, first era | E14: =E5 -> 0.81725742
A15: Smoothing ratio, last era | E15: =E12 -> 0.088891454
A16: Dividends became this many times smoother | E16: =E5/E12 -> 9.1938807

Sheet Crisis_Calc
A1: CRISIS DRAWDOWNS | INDEX/MATCH finds the pre-crisis peak, MIN finds the trough
A2: Base = the value in the first year of the crisis window. Trough = the minimum during the window. Drawdown = trough / base - 1. No regression, no assumptions.
A4: Crisis | B4: From | C4: To | D4: Base year | E4: Earnings fall | F4: Dividend fall | G4: Price fall | H4: Gap (earnings less dividend)
A5: Panic of 1873 | B5: 1873 | C5: 1879 | D5: =$B5 -> 1873 | E5: =MIN(INDEX(Data_Annual!$D$5:$D$157,MATCH($B5,Data_Annual!$A$5:$A$157,0)):INDEX(Data_Annual!$D$5:$D$157,MATCH($C5,Data_Annual!$A$5:$A$157,0)))/INDEX(Data_Annual!$D$5:$D$157,MATCH($D5,Data_Annual!$A$5:$A$157,0))-1 -> -0.34827264 | F5: =MIN(INDEX(Data_Annual!$C$5:$C$157,MATCH($B5,Data_Annual!$A$5:$A$157,0)):INDEX(Data_Annual!$C$5:$C$157,MATCH($C5,Data_Annual!$A$5:$A$157,0)))/INDEX(Data_Annual!$C$5:$C$157,MATCH($D5,Data_Annual!$A$5:$A$157,0))-1 -> -0.41633729 | G5: =MIN(INDEX(Data_Annual!$B$5:$B$157,MATCH($B5,Data_Annual!$A$5:$A$157,0)):INDEX(Data_Annual!$B$5:$B$157,MATCH($C5,Data_Annual!$A$5:$A$157,0)))/INDEX(Data_Annual!$B$5:$B$157,MATCH($D5,Data_Annual!$A$5:$A$157,0))-1 -> -0.34692815 | H5: =$E5-$F5 -> 0.068064644
A6: Panic of 1893 | B6: 1893 | C6: 1897 | D6: =$B6 -> 1893 | E6: =MIN(INDEX(Data_Annual!$D$5:$D$157,MATCH($B6,Data_Annual!$A$5:$A$157,0)):INDEX(Data_Annual!$D$5:$D$157,MATCH($C6,Data_Annual!$A$5:$A$157,0)))/INDEX(Data_Annual!$D$5:$D$157,MATCH($D6,Data_Annual!$A$5:$A$157,0))-1 -> -0.33691275 | F6: =MIN(INDEX(Data_Annual!$C$5:$C$157,MATCH($B6,Data_Annual!$A$5:$A$157,0)):INDEX(Data_Annual!$C$5:$C$157,MATCH($C6,Data_Annual!$A$5:$A$157,0)))/INDEX(Data_Annual!$C$5:$C$157,MATCH($D6,Data_Annual!$A$5:$A$157,0))-1 -> -0.26655348 | G6: =MIN(INDEX(Data_Annual!$B$5:$B$157,MATCH($B6,Data_Annual!$A$5:$A$157,0)):INDEX(Data_Annual!$B$5:$B$157,MATCH($C6,Data_Annual!$A$5:$A$157,0)))/INDEX(Data_Annual!$B$5:$B$157,MATCH($D6,Data_Annual!$A$5:$A$157,0))-1 -> -0.11343805 | H6: =$E6-$F6 -> -0.070359271
A7: Panic of 1907 | B7: 1907 | C7: 1908 | D7: =$B7 -> 1907 | E7: =MIN(INDEX(Data_Annual!$D$5:$D$157,MATCH($B7,Data_Annual!$A$5:$A$157,0)):INDEX(Data_Annual!$D$5:$D$157,MATCH($C7,Data_Annual!$A$5:$A$157,0)))/INDEX(Data_Annual!$D$5:$D$157,MATCH($D7,Data_Annual!$A$5:$A$157,0))-1 -> -0.12632822 | F7: =MIN(INDEX(Data_Annual!$C$5:$C$157,MATCH($B7,Data_Annual!$A$5:$A$157,0)):INDEX(Data_Annual!$C$5:$C$157,MATCH($C7,Data_Annual!$A$5:$A$157,0)))/INDEX(Data_Annual!$C$5:$C$157,MATCH($D7,Data_Annual!$A$5:$A$157,0))-1 -> -0.0079051383 | G7: =MIN(INDEX(Data_Annual!$B$5:$B$157,MATCH($B7,Data_Annual!$A$5:$A$157,0)):INDEX(Data_Annual!$B$5:$B$157,MATCH($C7,Data_Annual!$A$5:$A$157,0)))/INDEX(Data_Annual!$B$5:$B$157,MATCH($D7,Data_Annual!$A$5:$A$157,0))-1 -> -0.0081845238 | H7: =$E7-$F7 -> -0.11842308
A8: Great Depression | B8: 1929 | C8: 1933 | D8: =$B8 -> 1929 | E8: =MIN(INDEX(Data_Annual!$D$5:$D$157,MATCH($B8,Data_Annual!$A$5:$A$157,0)):INDEX(Data_Annual!$D$5:$D$157,MATCH($C8,Data_Annual!$A$5:$A$157,0)))/INDEX(Data_Annual!$D$5:$D$157,MATCH($D8,Data_Annual!$A$5:$A$157,0))-1 -> -0.71669898 | F8: =MIN(INDEX(Data_Annual!$C$5:$C$157,MATCH($B8,Data_Annual!$A$5:$A$157,0)):INDEX(Data_Annual!$C$5:$C$157,MATCH($C8,Data_Annual!$A$5:$A$157,0)))/INDEX(Data_Annual!$C$5:$C$157,MATCH($D8,Data_Annual!$A$5:$A$157,0))-1 -> -0.48907104 | G8: =MIN(INDEX(Data_Annual!$B$5:$B$157,MATCH($B8,Data_Annual!$A$5:$A$157,0)):INDEX(Data_Annual!$B$5:$B$157,MATCH($C8,Data_Annual!$A$5:$A$157,0)))/INDEX(Data_Annual!$B$5:$B$157,MATCH($D8,Data_Annual!$A$5:$A$157,0))-1 -> -0.73371341 | H8: =$E8-$F8 -> -0.22762794
A9: 1937 recession | B9: 1937 | C9: 1938 | D9: =$B9 -> 1937 | E9: =MIN(INDEX(Data_Annual!$D$5:$D$157,MATCH($B9,Data_Annual!$A$5:$A$157,0)):INDEX(Data_Annual!$D$5:$D$157,MATCH($C9,Data_Annual!$A$5:$A$157,0)))/INDEX(Data_Annual!$D$5:$D$157,MATCH($D9,Data_Annual!$A$5:$A$157,0))-1 -> -0.31132075 | F9: =MIN(INDEX(Data_Annual!$C$5:$C$157,MATCH($B9,Data_Annual!$A$5:$A$157,0)):INDEX(Data_Annual!$C$5:$C$157,MATCH($C9,Data_Annual!$A$5:$A$157,0)))/INDEX(Data_Annual!$C$5:$C$157,MATCH($D9,Data_Annual!$A$5:$A$157,0))-1 -> -0.1106383 | G9: =MIN(INDEX(Data_Annual!$B$5:$B$157,MATCH($B9,Data_Annual!$A$5:$A$157,0)):INDEX(Data_Annual!$B$5:$B$157,MATCH($C9,Data_Annual!$A$5:$A$157,0)))/INDEX(Data_Annual!$B$5:$B$157,MATCH($D9,Data_Annual!$A$5:$A$157,0))-1 -> -0.2542868 | H9: =$E9-$F9 -> -0.20068246
A10: Oil shock / stagflation | B10: 1973 | C10: 1975 | D10: =$B10 -> 1973 | E10: =MIN(INDEX(Data_Annual!$D$5:$D$157,MATCH($B10,Data_Annual!$A$5:$A$157,0)):INDEX(Data_Annual!$D$5:$D$157,MATCH($C10,Data_Annual!$A$5:$A$157,0)))/INDEX(Data_Annual!$D$5:$D$157,MATCH($D10,Data_Annual!$A$5:$A$157,0))-1 -> 0 | F10: =MIN(INDEX(Data_Annual!$C$5:$C$157,MATCH($B10,Data_Annual!$A$5:$A$157,0)):INDEX(Data_Annual!$C$5:$C$157,MATCH($C10,Data_Annual!$A$5:$A$157,0)))/INDEX(Data_Annual!$C$5:$C$157,MATCH($D10,Data_Annual!$A$5:$A$157,0))-1 -> 0 | G10: =MIN(INDEX(Data_Annual!$B$5:$B$157,MATCH($B10,Data_Annual!$A$5:$A$157,0)):INDEX(Data_Annual!$B$5:$B$157,MATCH($C10,Data_Annual!$A$5:$A$157,0)))/INDEX(Data_Annual!$B$5:$B$157,MATCH($D10,Data_Annual!$A$5:$A$157,0))-1 -> -0.23152171 | H10: =$E10-$F10 -> 0
A11: Dot-com bust | B11: 2000 | C11: 2002 | D11: =$B11 -> 2000 | E11: =MIN(INDEX(Data_Annual!$D$5:$D$157,MATCH($B11,Data_Annual!$A$5:$A$157,0)):INDEX(Data_Annual!$D$5:$D$157,MATCH($C11,Data_Annual!$A$5:$A$157,0)))/INDEX(Data_Annual!$D$5:$D$157,MATCH($D11,Data_Annual!$A$5:$A$157,0))-1 -> -0.47512462 | F11: =MIN(INDEX(Data_Annual!$C$5:$C$157,MATCH($B11,Data_Annual!$A$5:$A$157,0)):INDEX(Data_Annual!$C$5:$C$157,MATCH($C11,Data_Annual!$A$5:$A$157,0)))/INDEX(Data_Annual!$C$5:$C$157,MATCH($D11,Data_Annual!$A$5:$A$157,0))-1 -> -0.043843753 | G11: =MIN(INDEX(Data_Annual!$B$5:$B$157,MATCH($B11,Data_Annual!$A$5:$A$157,0)):INDEX(Data_Annual!$B$5:$B$157,MATCH($C11,Data_Annual!$A$5:$A$157,0)))/INDEX(Data_Annual!$B$5:$B$157,MATCH($D11,Data_Annual!$A$5:$A$157,0))-1 -> -0.30229519 | H11: =$E11-$F11 -> -0.43128087
A12: Global financial crisis | B12: 2007 | C12: 2009 | D12: =$B12 -> 2007 | E12: =MIN(INDEX(Data_Annual!$D$5:$D$157,MATCH($B12,Data_Annual!$A$5:$A$157,0)):INDEX(Data_Annual!$D$5:$D$157,MATCH($C12,Data_Annual!$A$5:$A$157,0)))/INDEX(Data_Annual!$D$5:$D$157,MATCH($D12,Data_Annual!$A$5:$A$157,0))-1 -> -0.79289848 | F12: =MIN(INDEX(Data_Annual!$C$5:$C$157,MATCH($B12,Data_Annual!$A$5:$A$157,0)):INDEX(Data_Annual!$C$5:$C$157,MATCH($C12,Data_Annual!$A$5:$A$157,0)))/INDEX(Data_Annual!$C$5:$C$157,MATCH($D12,Data_Annual!$A$5:$A$157,0))-1 -> -0.040473029 | G12: =MIN(INDEX(Data_Annual!$B$5:$B$157,MATCH($B12,Data_Annual!$A$5:$A$157,0)):INDEX(Data_Annual!$B$5:$B$157,MATCH($C12,Data_Annual!$A$5:$A$157,0)))/INDEX(Data_Annual!$B$5:$B$157,MATCH($D12,Data_Annual!$A$5:$A$157,0))-1 -> -0.35885517 | H12: =$E12-$F12 -> -0.75242545
A13: COVID-19 | B13: 2020 | C13: 2020 | D13: =$B13 -> 2020 | E13: =MIN(INDEX(Data_Annual!$D$5:$D$157,MATCH($B13,Data_Annual!$A$5:$A$157,0)):INDEX(Data_Annual!$D$5:$D$157,MATCH($C13,Data_Annual!$A$5:$A$157,0)))/INDEX(Data_Annual!$D$5:$D$157,MATCH($D13,Data_Annual!$A$5:$A$157,0))-1 -> 0 | F13: =MIN(INDEX(Data_Annual!$C$5:$C$157,MATCH($B13,Data_Annual!$A$5:$A$157,0)):INDEX(Data_Annual!$C$5:$C$157,MATCH($C13,Data_Annual!$A$5:$A$157,0)))/INDEX(Data_Annual!$C$5:$C$157,MATCH($D13,Data_Annual!$A$5:$A$157,0))-1 -> 0 | G13: =MIN(INDEX(Data_Annual!$B$5:$B$157,MATCH($B13,Data_Annual!$A$5:$A$157,0)):INDEX(Data_Annual!$B$5:$B$157,MATCH($C13,Data_Annual!$A$5:$A$157,0)))/INDEX(Data_Annual!$B$5:$B$157,MATCH($D13,Data_Annual!$A$5:$A$157,0))-1 -> 0 | H13: =$E13-$F13 -> 0
A15: CAVEAT - read before quoting the COVID-19 row. Because that window is a single year (2020 to 2020) and the base year is also 2020, the drawdown is zero by construction, not by observation. The same applies to any single-year window. The 1973-75 row reads zero for a different reason: nominal earnings never fell below their 1973 level during the window, because 1970s inflation held nominal figures up. Use the Great Depression and the global financial crisis rows for the headline comparison - those windows are long enough for the measure to mean something.

Sheet Firms_Data
A1: FIRM CROSS-SECTION | 466 current S&P 500 members | raw source data
A2: Source: S&P 500 constituents merged to financials on ticker. 466 of 503 matched; the 37 unmatched are recent additions and are excluded, not estimated.
A4: Ticker | B4: Company | C4: Sector | D4: Founded | E4: Age | F4: Dividend yield | G4: P/E | H4: P/B | I4: Pays?
A5: MMM | B5: 3M | C5: Industrials | D5: 1902 | E5: 124 | F5: 0.0181 | G5: 30.660744 | H5: 27.59271 | I5: =IF($F5>0,1,0) -> 1
A6: AOS | B6: A. O. Smith | C6: Industrials | D6: 1916 | E6: 110 | F6: 0.0237 | G6: 16.208 | H6: 4.4609175 | I6: =IF($F6>0,1,0) -> 1
A7: ABT | B7: Abbott Laboratories | C7: Health Care | D7: 1888 | E7: 138 | F7: 0.0245 | G7: 33.352753 | H7: 3.4480913 | I7: =IF($F7>0,1,0) -> 1
A8: ABBV | B8: AbbVie | C8: Health Care | D8: 2013 | E8: 13 | F8: 0.0267 | G8: 126.51707 | H8: -68.85054 | I8: =IF($F8>0,1,0) -> 1
A9: ACN | B9: Accenture | C9: Information Technology | D9: 1989 | E9: 37 | F9: 0.0444 | G9: 11.740416 | H9: 2.8201687 | I9: =IF($F9>0,1,0) -> 1
A10: ADBE | B10: Adobe Inc. | C10: Information Technology | D10: 1982 | E10: 44 | G10: 12.870784 | H10: 7.7981777 | I10: =IF($F10>0,1,0) -> 0
A11: AMD | B11: Advanced Micro Devices | C11: Information Technology | D11: 1969 | E11: 57 | G11: 175.15102 | H11: 13.19822 | I11: =IF($F11>0,1,0) -> 0
A12: AES | B12: AES Corporation | C12: Utilities | D12: 1981 | E12: 45 | F12: 0.0474 | G12: 7.729167 | H12: 2.3943207 | I12: =IF($F12>0,1,0) -> 1
A13: AFL | B13: Aflac | C13: Financials | D13: 1955 | E13: 71 | F13: 0.0194 | G13: 14.354285 | H13: 2.1402037 | I13: =IF($F13>0,1,0) -> 1
A14: A | B14: Agilent Technologies | C14: Health Care | D14: 1999 | E14: 27 | F14: 0.0074 | G14: 27.88129 | H14: 5.4909654 | I14: =IF($F14>0,1,0) -> 1
A15: APD | B15: Air Products | C15: Materials | D15: 1940 | E15: 86 | F15: 0.0243 | G15: 31.354736 | H15: 4.2383323 | I15: =IF($F15>0,1,0) -> 1
A16: ABNB | B16: Airbnb | C16: Consumer Discretionary | D16: 2008 | E16: 18 | G16: 34.839504 | H16: 10.994235 | I16: =IF($F16>0,1,0) -> 0
A17: AKAM | B17: Akamai Technologies | C17: Information Technology | D17: 1998 | E17: 28 | G17: 38.84512 | H17: 3.4208028 | I17: =IF($F17>0,1,0) -> 0
A18: ALB | B18: Albemarle Corporation | C18: Materials | D18: 1994 | E18: 32 | F18: 0.0143 | H18: 1.7779464 | I18: =IF($F18>0,1,0) -> 1
A19: ARE | B19: Alexandria Real Estate Equities | C19: Real Estate | D19: 1994 | E19: 32 | F19: 0.0565 | H19: 0.55269235 | I19: =IF($F19>0,1,0) -> 1
A20: ALGN | B20: Align Technology | C20: Health Care | D20: 1997 | E20: 29 | G20: 28.069748 | H20: 2.8826008 | I20: =IF($F20>0,1,0) -> 0
A21: ALLE | B21: Allegion | C21: Industrials | D21: 1908 | E21: 118 | F21: 0.0138 | G21: 20.125984 | H21: 6.1573052 | I21: =IF($F21>0,1,0) -> 1
A22: LNT | B22: Alliant Energy | C22: Utilities | D22: 1917 | E22: 109 | F22: 0.0286 | G22: 23.566038 | H22: 2.607788 | I22: =IF($F22>0,1,0) -> 1
A23: ALL | B23: Allstate | C23: Financials | D23: 1931 | E23: 95 | F23: 0.0166 | G23: 5.7502766 | H23: 2.2654943 | I23: =IF($F23>0,1,0) -> 1
A24: GOOGL | B24: Alphabet Inc. (Class A) | C24: Communication Services | D24: 1998 | E24: 28 | F24: 0.0028 | G24: 16.051205 | H24: 6.2822223 | I24: =IF($F24>0,1,0) -> 1
A25: GOOG | B25: Alphabet Inc. (Class C) | C25: Communication Services | D25: 1998 | E25: 28 | F25: 0.0028 | G25: 16.002506 | H25: 6.269451 | I25: =IF($F25>0,1,0) -> 1
A26: MO | B26: Altria | C26: Consumer Staples | D26: 1985 | E26: 41 | F26: 0.0581 | G26: 15.237995 | H26: -37.976063 | I26: =IF($F26>0,1,0) -> 1
A27: AMZN | B27: Amazon | C27: Consumer Discretionary | D27: 1994 | E27: 32 | G27: 27.764355 | H27: 5.6484075 | I27: =IF($F27>0,1,0) -> 0
A28: AMCR | B28: Amcor | C28: Materials | D28: 2019 | E28: 7 | F28: 0.0584 | G28: 35.632 | H28: 1.7666892 | I28: =IF($F28>0,1,0) -> 1
A29: AEE | B29: Ameren | C29: Utilities | D29: 1902 | E29: 124 | F29: 0.0264 | G29: 20.46403 | H29: 2.32242 | I29: =IF($F29>0,1,0) -> 1
A30: AEP | B30: American Electric Power | C30: Utilities | D30: 1906 | E30: 120 | F30: 0.028 | G30: 99.66176 | H30: 2.317993 | I30: =IF($F30>0,1,0) -> 1
A31: AXP | B31: American Express | C31: Financials | D31: 1850 | E31: 176 | F31: 0.0117 | G31: 19.803888 | H31: 6.5435543 | I31: =IF($F31>0,1,0) -> 1
A32: AIG | B32: American International Group | C32: Financials | D32: 1919 | E32: 107 | F32: 0.0253 | G32: 13.919014 | H32: 1.0427327 | I32: =IF($F32>0,1,0) -> 1
A33: AMT | B33: American Tower | C33: Real Estate | D33: 1995 | E33: 31 | F33: 0.0419 | G33: 26.88226 | H33: 22.049213 | I33: =IF($F33>0,1,0) -> 1
A34: AWK | B34: American Water Works | C34: Utilities | D34: 1886 | E34: 140 | F34: 0.0266 | G34: 23.875887 | H34: 2.3825617 | I34: =IF($F34>0,1,0) -> 1
A35: AMP | B35: Ameriprise Financial | C35: Financials | D35: 1894 | E35: 132 | F35: 0.0129 | G35: 131.56717 | H35: 7.669553 | I35: =IF($F35>0,1,0) -> 1
A36: AME | B36: Ametek | C36: Industrials | D36: 1930 | E36: 96 | F36: 0.0056 | G36: 36.496227 | H36: 5.0791354 | I36: =IF($F36>0,1,0) -> 1
A37: AMGN | B37: Amgen | C37: Health Care | D37: 1980 | E37: 46 | F37: 0.0268 | G37: 26.18663 | H37: 22.083628 | I37: =IF($F37>0,1,0) -> 1
A38: APH | B38: Amphenol | C38: Information Technology | D38: 1932 | E38: 94 | F38: 0.0066 | G38: 43.87069 | H38: 13.427441 | I38: =IF($F38>0,1,0) -> 1
A39: ADI | B39: Analog Devices | C39: Information Technology | D39: 1965 | E39: 61 | F39: 0.0118 | G39: 55.254086 | H39: 5.3680363 | I39: =IF($F39>0,1,0) -> 1
... A43: AMAT | B43: Applied Materials | C43: Information Technology | D43: 1967 | E43: 59 | F43: 0.004 | G43: 50.49435 | H43: 17.807331 | I43: =IF($F43>0,1,0) -> 1
A44: APTV | B44: Aptiv | C44: Consumer Discretionary | D44: 1994 | E44: 32 | G44: 33.660713 | H44: 1.300598 | I44: =IF($F44>0,1,0) -> 0
...

Sheet Sector_Calc
A1: WHO PAYS, BY SECTOR | COUNTIFS across the 466 firms
A4: Sector | B4: Firms | C4: Payers | D4: % paying | E4: Median yield of payers
A5: Communication Services | B5: =COUNTIFS(Firms_Data!$C$5:$C$470,$A5) -> 19 | C5: =COUNTIFS(Firms_Data!$C$5:$C$470,$A5,Firms_Data!$I$5:$I$470,1) -> 14 | D5: =IFERROR($C5/$B5,0) -> 0.73684211 | E5: =IFERROR(AVERAGEIFS(Firms_Data!$F$5:$F$470,Firms_Data!$C$5:$C$470,$A5,Firms_Data!$F$5:$F$470,">0"),0) -> 0.020935714
A6: Consumer Discretionary | B6: =COUNTIFS(Firms_Data!$C$5:$C$470,$A6) -> 44 | C6: =COUNTIFS(Firms_Data!$C$5:$C$470,$A6,Firms_Data!$I$5:$I$470,1) -> 31 | D6: =IFERROR($C6/$B6,0) -> 0.70454545 | E6: =IFERROR(AVERAGEIFS(Firms_Data!$F$5:$F$470,Firms_Data!$C$5:$C$470,$A6,Firms_Data!$F$5:$F$470,">0"),0) -> 0.020009677
A7: Consumer Staples | B7: =COUNTIFS(Firms_Data!$C$5:$C$470,$A7) -> 33 | C7: =COUNTIFS(Firms_Data!$C$5:$C$470,$A7,Firms_Data!$I$5:$I$470,1) -> 30 | D7: =IFERROR($C7/$B7,0) -> 0.90909091 | E7: =IFERROR(AVERAGEIFS(Firms_Data!$F$5:$F$470,Firms_Data!$C$5:$C$470,$A7,Firms_Data!$F$5:$F$470,">0"),0) -> 0.033836667
A8: Energy | B8: =COUNTIFS(Firms_Data!$C$5:$C$470,$A8) -> 19 | C8: =COUNTIFS(Firms_Data!$C$5:$C$470,$A8,Firms_Data!$I$5:$I$470,1) -> 19 | D8: =IFERROR($C8/$B8,0) -> 1 | E8: =IFERROR(AVERAGEIFS(Firms_Data!$F$5:$F$470,Firms_Data!$C$5:$C$470,$A8,Firms_Data!$F$5:$F$470,">0"),0) -> 0.0243
A9: Financials | B9: =COUNTIFS(Firms_Data!$C$5:$C$470,$A9) -> 67 | C9: =COUNTIFS(Firms_Data!$C$5:$C$470,$A9,Firms_Data!$I$5:$I$470,1) -> 64 | D9: =IFERROR($C9/$B9,0) -> 0.95522388 | E9: =IFERROR(AVERAGEIFS(Firms_Data!$F$5:$F$470,Firms_Data!$C$5:$C$470,$A9,Firms_Data!$F$5:$F$470,">0"),0) -> 0.020640625
A10: Health Care | B10: =COUNTIFS(Firms_Data!$C$5:$C$470,$A10) -> 58 | C10: =COUNTIFS(Firms_Data!$C$5:$C$470,$A10,Firms_Data!$I$5:$I$470,1) -> 38 | D10: =IFERROR($C10/$B10,0) -> 0.65517241 | E10: =IFERROR(AVERAGEIFS(Firms_Data!$F$5:$F$470,Firms_Data!$C$5:$C$470,$A10,Firms_Data!$F$5:$F$470,">0"),0) -> 0.016563158
A11: Industrials | B11: =COUNTIFS(Firms_Data!$C$5:$C$470,$A11) -> 75 | C11: =COUNTIFS(Firms_Data!$C$5:$C$470,$A11,Firms_Data!$I$5:$I$470,1) -> 67 | D11: =IFERROR($C11/$B11,0) -> 0.89333333 | E11: =IFERROR(AVERAGEIFS(Firms_Data!$F$5:$F$470,Firms_Data!$C$5:$C$470,$A11,Firms_Data!$F$5:$F$470,">0"),0) -> 0.014376119
A12: Information Technology | B12: =COUNTIFS(Firms_Data!$C$5:$C$470,$A12) -> 64 | C12: =COUNTIFS(Firms_Data!$C$5:$C$470,$A12,Firms_Data!$I$5:$I$470,1) -> 38 | D12: =IFERROR($C12/$B12,0) -> 0.59375 | E12: =IFERROR(AVERAGEIFS(Firms_Data!$F$5:$F$470,Firms_Data!$C$5:$C$470,$A12,Firms_Data!$F$5:$F$470,">0"),0) -> 0.013957895
A13: Materials | B13: =COUNTIFS(Firms_Data!$C$5:$C$470,$A13) -> 25 | C13: =COUNTIFS(Firms_Data!$C$5:$C$470,$A13,Firms_Data!$I$5:$I$470,1) -> 25 | D13: =IFERROR($C13/$B13,0) -> 1 | E13: =IFERROR(AVERAGEIFS(Firms_Data!$F$5:$F$470,Firms_Data!$C$5:$C$470,$A13,Firms_Data!$F$5:$F$470,">0"),0) -> 0.022816
A14: Real Estate | B14: =COUNTIFS(Firms_Data!$C$5:$C$470,$A14) -> 31 | C14: =COUNTIFS(Firms_Data!$C$5:$C$470,$A14,Firms_Data!$I$5:$I$470,1) -> 29 | D14: =IFERROR($C14/$B14,0) -> 0.93548387 | E14: =IFERROR(AVERAGEIFS(Firms_Data!$F$5:$F$470,Firms_Data!$C$5:$C$470,$A14,Firms_Data!$F$5:$F$470,">0"),0) -> 0.038182759
A15: Utilities | B15: =COUNTIFS(Firms_Data!$C$5:$C$470,$A15) -> 31 | C15: =COUNTIFS(Firms_Data!$C$5:$C$470,$A15,Firms_Data!$I$5:$I$470,1) -> 31 | D15: =IFERROR($C15/$B15,0) -> 1 | E15: =IFERROR(AVERAGEIFS(Firms_Data!$F$5:$F$470,Firms_Data!$C$5:$C$470,$A15,Firms_Data!$F$5:$F$470,">0"),0) -> 0.028648387
A17: ALL FIRMS | B17: =SUM(B5:B15) -> 466 | C17: =SUM(C5:C15) -> 386 | D17: =C17/B17 -> 0.82832618

Sheet LifeCycle_Calc
A1: LIFE-CYCLE TEST | does firm age predict paying a dividend? | COUNTIFS by age band
A2: DeAngelo, DeAngelo & Stulz (2006): firms begin paying once they mature and run out of investment opportunities. Founding year gives a direct test.
A4: Age band | B4: Lower | C4: Upper | D4: Firms | E4: Payers | F4: % paying | G4: Median yield of payers
A5: <25y | B5: 0 | C5: 25 | D5: =COUNTIFS(Firms_Data!$E$5:$E$470,">"&$B5,Firms_Data!$E$5:$E$470,"<="&$C5) -> 61 | E5: =COUNTIFS(Firms_Data!$E$5:$E$470,">"&$B5,Firms_Data!$E$5:$E$470,"<="&$C5,Firms_Data!$I$5:$I$470,1) -> 46 | F5: =IFERROR($E5/$D5,0) -> 0.75409836 | G5: =IFERROR(AVERAGEIFS(Firms_Data!$F$5:$F$470,Firms_Data!$E$5:$E$470,">"&$B5,Firms_Data!$E$5:$E$470,"<="&$C5,Firms_Data!$F$5:$F$470,">0"),0) -> 0.023286957
A6: 25-50y | B6: 25 | C6: 50 | D6: =COUNTIFS(Firms_Data!$E$5:$E$470,">"&$B6,Firms_Data!$E$5:$E$470,"<="&$C6) -> 153 | E6: =COUNTIFS(Firms_Data!$E$5:$E$470,">"&$B6,Firms_Data!$E$5:$E$470,"<="&$C6,Firms_Data!$I$5:$I$470,1) -> 108 | F6: =IFERROR($E6/$D6,0) -> 0.70588235 | G6: =IFERROR(AVERAGEIFS(Firms_Data!$F$5:$F$470,Firms_Data!$E$5:$E$470,">"&$B6,Firms_Data!$E$5:$E$470,"<="&$C6,Firms_Data!$F$5:$F$470,">0"),0) -> 0.020435185
A7: 50-75y | B7: 50 | C7: 75 | D7: =COUNTIFS(Firms_Data!$E$5:$E$470,">"&$B7,Firms_Data!$E$5:$E$470,"<="&$C7) -> 81 | E7: =COUNTIFS(Firms_Data!$E$5:$E$470,">"&$B7,Firms_Data!$E$5:$E$470,"<="&$C7,Firms_Data!$I$5:$I$470,1) -> 68 | F7: =IFERROR($E7/$D7,0) -> 0.83950617 | G7: =IFERROR(AVERAGEIFS(Firms_Data!$F$5:$F$470,Firms_Data!$E$5:$E$470,">"&$B7,Firms_Data!$E$5:$E$470,"<="&$C7,Firms_Data!$F$5:$F$470,">0"),0) -> 0.020726471
A8: 75-100y | B8: 75 | C8: 100 | D8: =COUNTIFS(Firms_Data!$E$5:$E$470,">"&$B8,Firms_Data!$E$5:$E$470,"<="&$C8) -> 46 | E8: =COUNTIFS(Firms_Data!$E$5:$E$470,">"&$B8,Firms_Data!$E$5:$E$470,"<="&$C8,Firms_Data!$I$5:$I$470,1) -> 43 | F8: =IFERROR($E8/$D8,0) -> 0.93478261 | G8: =IFERROR(AVERAGEIFS(Firms_Data!$F$5:$F$470,Firms_Data!$E$5:$E$470,">"&$B8,Firms_Data!$E$5:$E$470,"<="&$C8,Firms_Data!$F$5:$F$470,">0"),0) -> 0.02095814
A9: 100-150y | B9: 100 | C9: 150 | D9: =COUNTIFS(Firms_Data!$E$5:$E$470,">"&$B9,Firms_Data!$E$5:$E$470,"<="&$C9) -> 91 | E9: =COUNTIFS(Firms_Data!$E$5:$E$470,">"&$B9,Firms_Data!$E$5:$E$470,"<="&$C9,Firms_Data!$I$5:$I$470,1) -> 89 | F9: =IFERROR($E9/$D9,0) -> 0.97802198 | G9: =IFERROR(AVERAGEIFS(Firms_Data!$F$5:$F$470,Firms_Data!$E$5:$E$470,">"&$B9,Firms_Data!$E$5:$E$470,"<="&$C9,Firms_Data!$F$5:$F$470,">0"),0) -> 0.02241236
A10: 150y+ | B10: 150 | C10: 400 | D10: =COUNTIFS(Firms_Data!$E$5:$E$470,">"&$B10,Firms_Data!$E$5:$E$470,"<="&$C10) -> 34 | E10: =COUNTIFS(Firms_Data!$E$5:$E$470,">"&$B10,Firms_Data!$E$5:$E$470,"<="&$C10,Firms_Data!$I$5:$I$470,1) -> 32 | F10: =IFERROR($E10/$D10,0) -> 0.94117647 | G10: =IFERROR(AVERAGEIFS(Firms_Data!$F$5:$F$470,Firms_Data!$E$5:$E$470,">"&$B10,Firms_Data!$E$5:$E$470,"<="&$C10,Firms_Data!$F$5:$F$470,">0"),0) -> 0.025515625
A12: Life-cycle gradient (oldest band less youngest) | F12: =F9-F5 -> 0.22392362
